<?xml version="1.0"?>
<robot xmlns:xacro="http://ros.org/wiki/xacro" name="table_rail_montage">

  <!-- Table -->
  <link name="table">
    <visual>
      <origin xyz="0 0 0.5"/>
      <geometry><box size="0.5 2 1"/></geometry>
      <material name="grey"><color rgba="0.6 0.6 0.6 1.0"/></material>
    </visual>
    <collision>
      <origin xyz="0 0 0.5"/>
      <geometry><box size="0.5 2 1"/></geometry>
    </collision>
  </link>

  <!-- Rail sur la table-->
  <link name="rail">
    <visual>
      <origin xyz="0 0 1.01"/>
      <geometry><box size="0.20 1.9 0.02"/></geometry>
      <material name="blue"><color rgba="0 0 1 1.0"/></material>
    </visual>
    <collision>
      <origin xyz="0 0 1.01"/>
      <geometry><box size="0.20 1.9 0.02"/></geometry>
    </collision>
  </link>
  

  <joint name="table_to_rail" type="fixed">
    <parent link="table"/>
    <child link="rail"/>
    <origin xyz="0 0 0"/>
  </joint>

  <!-- La pièce qui glisse ("montage") -->
  <link name="montage">
    <visual>
      <origin xyz="0.0 0 1.03"/>
      <geometry><box size="0.2 0.2 0.02"/></geometry>
      <material name="red"><color rgba="1 0 0 1.0"/></material>
    </visual>
    <collision>
      <origin xyz="0.0 0 1.03"/>
      <geometry><box size="0.2 0.2 0.02"/></geometry>
    </collision>
  </link>

  <joint name="rail_joint" type="prismatic">
    <origin xyz="0 -0.85 0" rpy="0 0 0"/>
    <parent link="rail"/>
    <child link="montage"/>
    <axis xyz="0 1 0"/>
    <limit lower="0" upper="1.7" effort="1000" velocity="0.5"/>
  </joint>
  
  


</robot>